<?xml version="1.0" ?>
<!-- =================================================================================== -->
<!-- |    This document was autogenerated by xacro from arm_v1.xacro                   | -->
<!-- |    EDITING THIS FILE BY HAND IS NOT RECOMMENDED                                 | -->
<!-- =================================================================================== -->
<robot name="arm_v1">
  <mujoco>
    <compiler balanceinertia="true" discardvisual="false" meshdir="meshes/arm/"/>
  </mujoco>
  <link name="dummy_base_link"/>
  <link name="arm_base_link">
    <inertial>
      <origin rpy="0 0 0" xyz="0.000175438965895703 0.000532268611608213 0.0522669336069407"/>
      <mass value="0.294119348658744"/>
      <inertia ixx="0.00032400532756564" ixy="-5.40018128899478E-07" ixz="2.80958833443407E-06" iyy="0.000288426609563467" iyz="4.70285799717824E-06" izz="0.00022606419233657"/>
    </inertial>
    <visual>
      <origin rpy="0 0 0" xyz="0 0 0"/>
      <geometry>
        <mesh filename="package://arm_v1/meshes/arm/base_link.STL"/>
      </geometry>
      <material name="">
        <color rgba="0.752941176470588 0.752941176470588 0.752941176470588 1"/>
      </material>
    </visual>
  </link>
  <link name="arm_L1">
    <inertial>
      <origin rpy="0 0 0" xyz="0.0698160338667713 -0.0143691484806762 0.0110780451265005"/>
      <mass value="0.0556965417664696"/>
      <inertia ixx="2.706330396577111E-05" ixy="6.264494073241328E-06" ixz="7.579004552737409E-06" iyy="1.226796883628498E-04" iyz="1.359443408382777E-08" izz="1.314431374103430E-04"/>
    </inertial>
    <visual>
      <origin rpy="0 0 3.1416" xyz="0 0 0"/>
      <geometry>
        <mesh filename="package://arm_v1/meshes/arm/L1.STL"/>
      </geometry>
      <material name="">
        <color rgba="0.752941176470588 0.752941176470588 0.752941176470588 1"/>
      </material>
    </visual>
  </link>
  <joint name="arm_J1" type="revolute">
    <origin rpy="0.000000000 0.000000000 0.000000000" xyz="0.000000000 0.000000000 0.0962     "/>
    <parent link="arm_base_link"/>
    <child link="arm_L1"/>
    <axis xyz="0 0 1"/>
    <limit effort="100" lower="-3.14159265" upper="3.14159265" velocity="5.0"/>
  </joint>
  <link name="arm_L2">
    <inertial>
      <origin rpy="0 0 0" xyz="0.181439379971025 -0.000243727779993763 0.0563566127647854"/>
      <mass value="0.6"/>
      <inertia ixx="6.36253645667139E-05" ixy="-2.59780400404477E-07" ixz="3.91165512368072E-05" iyy="0.00232680960984668" iyz="2.19730518054456E-07" izz="0.00235460000620241"/>
    </inertial>
    <visual>
      <origin rpy="0 0 0" xyz="0 0 0"/>
      <geometry>
        <mesh filename="package://arm_v1/meshes/arm/L2.STL"/>
      </geometry>
      <material name="">
        <color rgba="0.752941176470588 0.752941176470588 0.752941176470588 1"/>
      </material>
    </visual>
  </link>
  <joint name="arm_J2" type="revolute">
    <origin rpy=" -1.57079632  -1.57079632  0.000000000" xyz=" 0.0965       0.000000000  0.000000000"/>
    <parent link="arm_L1"/>
    <child link="arm_L2"/>
    <axis xyz="0 0 1"/>
    <limit effort="100" lower="-1.57079632" upper="1.57079632" velocity="5.0"/>
  </joint>
  <link name="arm_L3">
    <inertial>
      <origin rpy="0 0 0" xyz="0.0769703538179346 0.0011973381819983 -0.036630608037162"/>
      <mass value="0.10"/>
      <inertia ixx="2.84299236389363E-05" ixy="-7.63642211997418E-08" ixz="-3.24526804421142E-06" iyy="0.00034423782372923" iyz="7.76643137920171E-08" izz="0.000355286583426244"/>
    </inertial>
    <visual>
      <origin rpy="0 0 0" xyz="0 0 0"/>
      <geometry>
        <mesh filename="package://arm_v1/meshes/arm/L3.STL"/>
      </geometry>
      <material name="">
        <color rgba="0.752941176470588 0.752941176470588 0.752941176470588 1"/>
      </material>
    </visual>
  </link>
  <joint name="arm_J3" type="revolute">
    <origin rpy=" 0.000000000  0.000000000  0.000000000" xyz=" 0.3465       0.000000000  0.000000000"/>
    <parent link="arm_L2"/>
    <child link="arm_L3"/>
    <axis xyz="0 0 1"/>
    <limit effort="100" lower="-3.14159265" upper="3.14159265" velocity="5.0"/>
  </joint>
  <link name="arm_L4">
    <inertial>
      <origin rpy="0 0 0" xyz="0.000159906636227225 0.0237750547972229 0.0101176007477914"/>
      <mass value="0.10"/>
      <inertia ixx="2.567586853610741E-05" ixy="2.809499479363630E-08" ixz="-5.663869653767666E-09" iyy="1.103400538541320E-05" iyz="4.223539115427642E-06" izz="1.971338115301730E-05"/>
    </inertial>
    <visual>
      <origin rpy="0 0 3.14159265" xyz="0 0 0"/>
      <geometry>
        <mesh filename="package://arm_v1/meshes/arm/L4.STL"/>
      </geometry>
      <material name="">
        <color rgba="0.752941176470588 0.752941176470588 0.752941176470588 1"/>
      </material>
    </visual>
  </link>
  <joint name="arm_J4" type="revolute">
    <origin rpy=" 0.000000000  0.000000000  0.000000000" xyz=" 0.15         0.000000000  0.000000000"/>
    <parent link="arm_L3"/>
    <child link="arm_L4"/>
    <axis xyz="0 0 1"/>
    <limit effort="100" lower="-3.92699" upper="0.872664" velocity="5.0"/>
  </joint>
  <link name="arm_L5">
    <inertial>
      <origin rpy="0 0 0" xyz="4.0073722048969E-05 0.0692610166439792 0.00106706924657128"/>
      <mass value="0.25"/>
      <inertia ixx="0.000178750470884079" ixy="-5.70038950626815E-08" ixz="2.3383845024287E-08" iyy="8.0271837143644E-05" iyz="2.62896263229073E-06" izz="0.000152690614441042"/>
    </inertial>
    <visual>
      <origin rpy="0 0 0" xyz="0 0 0"/>
      <geometry>
        <mesh filename="package://arm_v1/meshes/arm/L5.STL"/>
      </geometry>
      <material name="">
        <color rgba="0.752941176470588 0.752941176470588 0.752941176470588 1"/>
      </material>
    </visual>
  </link>
  <joint name="arm_J5" type="revolute">
    <origin rpy=" -1.57079632  -1.57079632  0.000000000" xyz=" 0.000000000  0.0965      0.000000000"/>
    <parent link="arm_L4"/>
    <child link="arm_L5"/>
    <axis xyz="0 0 1"/>
    <limit effort="100" lower="-3.14159265" upper="3.14159265" velocity="5.0"/>
  </joint>
  <link name="arm_L6">
    <inertial>
      <origin rpy="0 0 0" xyz="1.77592382908782E-07 1.02533046673927E-07 0.00864548755955175"/>
      <mass value="0.15"/>
      <inertia ixx="8.03963570266054E-06" ixy="7.7682030591729E-11" ixz="-6.48485539118529E-12" iyy="8.039546003178E-06" iyz="-3.74403298061715E-12" izz="1.53036652434403E-05"/>
    </inertial>
    <visual>
      <origin rpy="0 0 0" xyz="0 0 0"/>
      <geometry>
        <mesh filename="package://arm_v1/meshes/arm/L6.STL"/>
      </geometry>
      <material name="">
        <color rgba="1 1 1 1"/>
      </material>
    </visual>
  </link>
  <joint name="arm_J6" type="revolute">
    <origin rpy=" -1.57079632  0.000000000  0.000000000" xyz=" 0.000000000  0.185  0.000000000"/>
    <parent link="arm_L5"/>
    <child link="arm_L6"/>
    <axis xyz="0 0 1"/>
    <limit effort="100" lower="-6.2831853" upper="6.2831853" velocity="5.0"/>
  </joint>
  <link name="arm_end_effector">
        </link>
  <joint name="arm_J7" type="fixed">
    <origin rpy="0 0 0" xyz="0 0 0.01"/>
    <parent link="arm_L6"/>
    <child link="arm_end_effector"/>
  </joint>
  <joint name="J0" type="fixed">
    <origin rpy="0 0 0" xyz="0 0 0"/>
    <parent link="dummy_base_link"/>
    <child link="arm_base_link"/>
  </joint>
</robot>
